Workbook

Sheet Overview
A1: Study Tracker - Fall 2026 seed workbook (NAIT Instrumentation Engineering Technology, lab section X02)
A3: Built from Semester1.zip on 2026-09-02. Yellow cells = edit me. See README sheet for how each sheet is used.
A5: course_id | B5: code | C5: name | D5: target_grade | E5: theory weight % | F5: lab weight % | G5: total weight % | H5: weights OK? | I5: topics | J5: exams/assessments listed | K5: lab sessions listed | L5: open flags
A6: 1 | B6: CMTC2341 | C6: Data Communications | D6: =INDEX(Courses!$J$2:$J$100,MATCH(A6,Courses!$A$2:$A$100,0)) -> 80 | E6: =SUMIFS(GradeWeights!$E$2:$E$500,GradeWeights!$B$2:$B$500,A6,GradeWeights!$C$2:$C$500,"Theory") -> 88 | F6: =SUMIFS(GradeWeights!$E$2:$E$500,GradeWeights!$B$2:$B$500,A6,GradeWeights!$C$2:$C$500,"Lab") -> 12 | G6: =E6+F6 -> 100 | H6: =IF(ABS(G6-100)<0.01,"OK","CHECK") -> OK | I6: =COUNTIF(Topics!$B$2:$B$2000,A6) -> 50 | J6: =COUNTIF(Assessments!$B$2:$B$2000,A6) -> 3 | K6: =COUNTIF(PreLabs!$B$2:$B$2000,A6) -> 8 | L6: =COUNTIFS(SyllabusFlags!$B$2:$B$500,A6,SyllabusFlags!$F$2:$F$500,"FALSE") -> 4
A7: 2 | B7: CNTR2371 | C7: Process Control I | D7: =INDEX(Courses!$J$2:$J$100,MATCH(A7,Courses!$A$2:$A$100,0)) -> 80 | E7: =SUMIFS(GradeWeights!$E$2:$E$500,GradeWeights!$B$2:$B$500,A7,GradeWeights!$C$2:$C$500,"Theory") -> 80 | F7: =SUMIFS(GradeWeights!$E$2:$E$500,GradeWeights!$B$2:$B$500,A7,GradeWeights!$C$2:$C$500,"Lab") -> 20 | G7: =E7+F7 -> 100 | H7: =IF(ABS(G7-100)<0.01,"OK","CHECK") -> OK | I7: =COUNTIF(Topics!$B$2:$B$2000,A7) -> 59 | J7: =COUNTIF(Assessments!$B$2:$B$2000,A7) -> 5 | K7: =COUNTIF(PreLabs!$B$2:$B$2000,A7) -> 15 | L7: =COUNTIFS(SyllabusFlags!$B$2:$B$500,A7,SyllabusFlags!$F$2:$F$500,"FALSE") -> 4
A8: 3 | B8: INST2310 | C8: Process Measurements III | D8: =INDEX(Courses!$J$2:$J$100,MATCH(A8,Courses!$A$2:$A$100,0)) -> 80 | E8: =SUMIFS(GradeWeights!$E$2:$E$500,GradeWeights!$B$2:$B$500,A8,GradeWeights!$C$2:$C$500,"Theory") -> 80 | F8: =SUMIFS(GradeWeights!$E$2:$E$500,GradeWeights!$B$2:$B$500,A8,GradeWeights!$C$2:$C$500,"Lab") -> 20 | G8: =E8+F8 -> 100 | H8: =IF(ABS(G8-100)<0.01,"OK","CHECK") -> OK | I8: =COUNTIF(Topics!$B$2:$B$2000,A8) -> 50 | J8: =COUNTIF(Assessments!$B$2:$B$2000,A8) -> 5 | K8: =COUNTIF(PreLabs!$B$2:$B$2000,A8) -> 14 | L8: =COUNTIFS(SyllabusFlags!$B$2:$B$500,A8,SyllabusFlags!$F$2:$F$500,"FALSE") -> 3
A9: 4 | B9: INST2340 | C9: Industrial Programming | D9: =INDEX(Courses!$J$2:$J$100,MATCH(A9,Courses!$A$2:$A$100,0)) -> 80 | E9: =SUMIFS(GradeWeights!$E$2:$E$500,GradeWeights!$B$2:$B$500,A9,GradeWeights!$C$2:$C$500,"Theory") -> 75 | F9: =SUMIFS(GradeWeights!$E$2:$E$500,GradeWeights!$B$2:$B$500,A9,GradeWeights!$C$2:$C$500,"Lab") -> 25 | G9: =E9+F9 -> 100 | H9: =IF(ABS(G9-100)<0.01,"OK","CHECK") -> OK | I9: =COUNTIF(Topics!$B$2:$B$2000,A9) -> 43 | J9: =COUNTIF(Assessments!$B$2:$B$2000,A9) -> 6 | K9: =COUNTIF(PreLabs!$B$2:$B$2000,A9) -> 15 | L9: =COUNTIFS(SyllabusFlags!$B$2:$B$500,A9,SyllabusFlags!$F$2:$F$500,"FALSE") -> 4
A10: 5 | B10: INST2361 | C10: Instrumentation Engineering I | D10: =INDEX(Courses!$J$2:$J$100,MATCH(A10,Courses!$A$2:$A$100,0)) -> 80 | E10: =SUMIFS(GradeWeights!$E$2:$E$500,GradeWeights!$B$2:$B$500,A10,GradeWeights!$C$2:$C$500,"Theory") -> 80 | F10: =SUMIFS(GradeWeights!$E$2:$E$500,GradeWeights!$B$2:$B$500,A10,GradeWeights!$C$2:$C$500,"Lab") -> 20 | G10: =E10+F10 -> 100 | H10: =IF(ABS(G10-100)<0.01,"OK","CHECK") -> OK | I10: =COUNTIF(Topics!$B$2:$B$2000,A10) -> 32 | J10: =COUNTIF(Assessments!$B$2:$B$2000,A10) -> 0 | K10: =COUNTIF(PreLabs!$B$2:$B$2000,A10) -> 15 | L10: =COUNTIFS(SyllabusFlags!$B$2:$B$500,A10,SyllabusFlags!$F$2:$F$500,"FALSE") -> 3
A11: 6 | B11: INST2380 | C11: Analyzers I | D11: =INDEX(Courses!$J$2:$J$100,MATCH(A11,Courses!$A$2:$A$100,0)) -> 80 | E11: =SUMIFS(GradeWeights!$E$2:$E$500,GradeWeights!$B$2:$B$500,A11,GradeWeights!$C$2:$C$500,"Theory") -> 80 | F11: =SUMIFS(GradeWeights!$E$2:$E$500,GradeWeights!$B$2:$B$500,A11,GradeWeights!$C$2:$C$500,"Lab") -> 20 | G11: =E11+F11 -> 100 | H11: =IF(ABS(G11-100)<0.01,"OK","CHECK") -> OK | I11: =COUNTIF(Topics!$B$2:$B$2000,A11) -> 13 | J11: =COUNTIF(Assessments!$B$2:$B$2000,A11) -> 1 | K11: =COUNTIF(PreLabs!$B$2:$B$2000,A11) -> 14 | L11: =COUNTIFS(SyllabusFlags!$B$2:$B$500,A11,SyllabusFlags!$F$2:$F$500,"FALSE") -> 4
A14: Timetable (all sections A01 lecture / X02 lab) - see Schedule sheet. Holidays: Sep 7, Sep 30, Oct 12, Nov 11-13.
A15: Grade weights for INST2361 and INST2380 theory are PLACEHOLDERS (no syllabus in the export) - fix them in GradeWeights.

Sheet README
A1: How to use this workbook
A2: This is the seed data for the Study Tracker app. The app reads/writes it; you can also edit it directly in Excel (close Excel before the app saves).
A3: Yellow-filled cells are the ones you are expected to edit by hand: target_grade, status/confidence on Topics, score on Assessments, completed on PreLabs.
A5: File paths
A6: All paths in Materials / Topics.link / PreLabs.link are relative to data/. Unzip Semester1.zip so that the nested course zips are extracted into data/coursepacks/<COURSECODE>/ (the CNTR2371 lab zip into data/coursepacks/CNTR2371_LAB/). The three loose syllabus files, SCHEDULE.pdf and Course Pack 1.pdf go straight into data/coursepacks/.
A7: The app's start-up routine auto-extracts any *.zip dropped into data/coursepacks/ using the first word of the zip file name as the folder name (appending _LAB when the name ends in 'LAB.zip').
A9: Sheets
A10: Courses - one row per course. lab_section = X02 for everything this term. min_lab_completion_pct = labs you must complete (75%, INST2310 80%).
A11: Materials - every PDF/DOCX from the export; drives the dynamic 'Open ...' buttons.
A12: GradeWeights - evaluation tables from the syllabi. component = Theory or Lab (NAIT requires >= 50% in EACH). Rows marked PLACEHOLDER must be replaced.
A13: Topics - syllabus sections/sub-sections with a link to the PDF and the PDF page to open. Change status as you go: Not Started -> Copied -> Learning / Needs Focus -> Mastered.
A14: Assessments - every exam, midterm, practical in-lab assessment and project with the best-known date. Read notes: many dates are 'week of' or inferred. topic_ids = topics the exam covers.
... A24: Topics row 2 shows the expected format (course 1, section 1.1, link + page). PreLabs row 2 shows a checklist. PracticeQuestions row 2 shows a Short Answer question; row 3 an MCQ with pipe-separated options.

Sheet Courses
A1: course_id | B1: code | C1: name | D1: term | E1: instructor | F1: email | G1: office | H1: lecture_section | I1: lab_section | J1: target_grade | K1: color_hex | L1: syllabus_path | M1: theory_coursepack | N1: lab_coursepack | O1: min_lab_completion_pct | P1: notes | Q1: active
A2: 1 | B2: CMTC2341 | C2: Data Communications | D2: Fall 2026 | E2: Ali Ali | F2: aali@nait.ca | G2: Y304X (ph 780-378-7134) | H2: A01 | I2: X02 | J2: 80 | K2: #2E86DE | L2: coursepacks/CMTC2341/Course Syllabus CMTC2341 Fall 2026 B.pdf | M2: #1400 | N2: #1400 | O2: 75 | P2: Pass/Fail course, 50% min. Theory AND Lab each >=50%. Brightspace. Bring memory stick. | Q2: =TRUE() -> TRUE
A3: 2 | B3: CNTR2371 | C3: Process Control I | D3: Fall 2026 | E3: Gordon Cutting | F3: gordonc@nait.ca | G3: Y305 | H3: A01 | I3: X02 | J3: 80 | K3: #E17055 | L3: coursepacks/CNTR 2371 Syllabus Fall 2026.pdf | M3: #3251 | N3: #3252 | O3: 75 | P3: Theory AND Lab each >=50%, course avg >=50%. Labs in pairs; pre-labs done individually before lab. TI-84+, CSA safety glasses, instrument screwdriver. | Q3: =TRUE() -> TRUE
A4: 3 | B4: INST2310 | C4: Process Measurements III | D4: Fall 2026 | E4: Daniela Ventura | F4: dventura@nait.ca | G4: Y304V (ph 780-491-3074) | H4: A01 | I4: X02 | J4: 80 | K4: #00B894 | L4: coursepacks/INST2310 Course Syllabus 2026.docx | M4: #1233 | N4: #1341 | O4: 80 | P4: Theory AND Lab each >=50%. Must complete 80% of labs. Labs 5-10 rotational. No phones in class. | Q4: =TRUE() -> TRUE
A5: 4 | B5: INST2340 | C5: Industrial Programming | D5: Fall 2026 | E5: Ali Ali | F5: aali@nait.ca | G5: Y304X (ph 780-378-7134) | H5: A01 | I5: X02 | J5: 80 | K5: #6C5CE7 | L5: coursepacks/INST2340 Syllabus Fall 2026 (ALi - for posting).pdf | M5: #1749 | N5: #1749 | O5: 75 | P5: Lecture AND Lab each >=50%. Lab attendance compulsory. Sign-off sections in every lab. Lab project from week 7/9. Pre-labs >= 30% of lab mark. | Q5: =TRUE() -> TRUE
A6: 5 | B6: INST2361 | C6: Instrumentation Engineering I | D6: Fall 2026 | E6: (not in export) | H6: A01 | I6: X02 | J6: 80 | K6: #FDCB6E | M6: #3253 | N6: #3253 | O6: 75 | P6: NO SYLLABUS IN EXPORT - grade weights are placeholders. Labs: Excel, SmartSketch, MS Project, valve sizing, AutoCAD/Visio. | Q6: =TRUE() -> TRUE
A7: 6 | B7: INST2380 | C7: Analyzers I | D7: Fall 2026 | E7: Melody Dalley (lab, per F2025 syllabus) | F7: melodyd@nait.ca | H7: A01 | I7: X02 | J7: 80 | K7: #D63031 | L7: coursepacks/INST2380 Lab Syllabus F2025.pdf | M7: #3015 | N7: #3015 | O7: 75 | P7: Lab = 20% (5% pre-lab quizzes+orientation, 15% in-lab+write-up). Pre-lab quiz on Brightspace >=50%, >=15 min before lab, FIRST attempt counts. Lab summary due end of period. Lab coat + safety glasses + long pants. 6 of 8 labs required. Theory weights NOT in export. | Q7: =TRUE() -> TRUE

Sheet Materials
A1: material_id | B1: course_id | C1: label | D1: kind | E1: path | F1: sort_order
A2: 1 | B2: 1 | C2: Coursepack CP#1400 (theory + labs) | D2: Coursepack | E2: coursepacks/CMTC2341/Content/CP#1400 - CMTC 2341.pdf | F2: 1
A3: 2 | B3: 1 | C3: Course Syllabus Fall 2026 | D3: Syllabus | E3: coursepacks/CMTC2341/Course Syllabus CMTC2341 Fall 2026 B.pdf | F3: 2
A4: 3 | B4: 1 | C4: Course Outline 2026/27 (outcomes) | D4: Course Outline | E4: coursepacks/CMTC2341/CMTC2341 Course Outline 2026_27.pdf | F4: 3
A5: 4 | B5: 2 | C5: Syllabus Fall 2026 | D5: Syllabus | E5: coursepacks/CNTR 2371 Syllabus Fall 2026.pdf | F5: 1
A6: 5 | B6: 2 | C6: Course Overview | D6: Coursepack | E6: coursepacks/CNTR2371/00 - CNTR2371 Course Overview.pdf | F6: 2
A7: 6 | B7: 2 | C7: Theory Section 1 | D7: Coursepack | E7: coursepacks/CNTR2371/01 - Section 1 - Basic Control Loop.pdf | F7: 11
A8: 7 | B8: 2 | C8: Theory Section 2 | D8: Coursepack | E8: coursepacks/CNTR2371/02 - Section 2 - Basic Process Characteristics.pdf | F8: 12
A9: 8 | B9: 2 | C9: Theory Section 3 | D9: Coursepack | E9: coursepacks/CNTR2371/03 - Section 3 - Characteristics of a Multicapacity Plant.pdf | F9: 13
A10: 9 | B10: 2 | C10: Theory Section 4 | D10: Coursepack | E10: coursepacks/CNTR2371/04 - Section 4 - Issues with Basic Feedback Control Loop_Updated_May2025.pdf | F10: 14
A11: 10 | B11: 2 | C11: Theory Section 5 | D11: Coursepack | E11: coursepacks/CNTR2371/05 - Section 5 - Feedback Controller Tuning_Updated_May2025.pdf | F11: 15
A12: 11 | B12: 2 | C12: Theory Section 6 | D12: Coursepack | E12: coursepacks/CNTR2371/06 - Section 6 - Closed Loop Response Characteristics_Updated_May2025.pdf | F12: 16
A13: 12 | B13: 2 | C13: Theory Section 7 | D13: Coursepack | E13: coursepacks/CNTR2371/07 - Section 7 - Frequency Analysis_Updated_May2025.pdf | F13: 17
... A119: 118 | B119: 6 | C119: Lab procedure - Flame and Smoke Detection | D119: Lab Procedure | E119: coursepacks/INST2380/14 - Flame and Smoke Detection.docx | F119: 56
A120: 119 | B120: 6 | C120: Alberta Apprenticeship ILMs (required theory - NOT in export) | D120: Other | F120: 99

Sheet GradeWeights
A1: weight_id | B1: course_id | C1: component | D1: category | E1: weight_pct | F1: drop_lowest | G1: notes
A2: 1 | B2: 1 | C2: Theory | D2: In-class / take-home assessments | E2: 22 | F2: 0 | G2: Weeks 2-14, due dates on Brightspace
A3: 2 | B3: 1 | C3: Lab | D3: Lab evaluations | E3: 12 | F3: 0 | G3: Weeks 1-14, rubrics on Brightspace
A4: 3 | B4: 1 | C4: Theory | D4: Theory Assessment 1 | E4: 22 | F4: 0 | G4: Outcomes 1-2
A5: 4 | B5: 1 | C5: Theory | D5: Theory Assessment 2 | E5: 22 | F5: 0 | G5: Outcome 3
A6: 5 | B6: 1 | C6: Theory | D6: Theory Assessment 3 | E6: 22 | F6: 0 | G6: Outcomes 4-5
A7: 6 | B7: 2 | C7: Lab | D7: Lab assessments | E7: 5 | F7: 0 | G7: Weeks 1-15
A8: 7 | B8: 2 | C8: Lab | D8: Practical In-Lab Assessment 1 | E8: 7.5 | F8: 0 | G8: Week 5 or 6
A9: 8 | B9: 2 | C9: Lab | D9: Practical In-Lab Assessment 2 | E9: 7.5 | F9: 0 | G9: Week 9 or 10
A10: 9 | B10: 2 | C10: Theory | D10: In-class / take-home assessments | E10: 15 | F10: 0 | G10: Weeks 1-15
A11: 10 | B11: 2 | C11: Theory | D11: Theory Assessment 1 | E11: 20 | F11: 0 | G11: Sections 1-3
A12: 11 | B12: 2 | C12: Theory | D12: Theory Assessment 2 | E12: 20 | F12: 0 | G12: Sections 4-5
A13: 12 | B13: 2 | C13: Theory | D13: Theory Assessment 3 | E13: 25 | F13: 0 | G13: Sections 6-8
... A31: 30 | B31: 6 | C31: Theory | D31: Theory (PLACEHOLDER) | E31: 80 | F31: 0 | G31: PLACEHOLDER - INST2380 theory syllabus not in export. Replace.

Sheet Topics
A1: topic_id | B1: course_id | C1: unit | D1: section | E1: title | F1: status | G1: confidence | H1: priority | I1: link | J1: page | K1: estimated_hours | L1: last_reviewed | M1: next_review | N1: notes
A2: 1 | B2: 1 | C2: Section 1 - Data Communications Overview | D2: 1.1 | E2: Industrial data comms & the 3 network levels (information / control / field device) | F2: Not Started | G2: 1 | H2: 3 | I2: coursepacks/CMTC2341/Content/CP#1400 - CMTC 2341.pdf | J2: 1 | K2: 1.5
A3: 2 | B3: 1 | C3: Section 1 - Data Communications Overview | D3: 1.2 | E3: DTE, DCE, DTE/DCE interface, transmission channel | F3: Not Started | G3: 1 | H3: 3 | I3: coursepacks/CMTC2341/Content/CP#1400 - CMTC 2341.pdf | J3: 3 | K3: 1.5
A4: 3 | B4: 1 | C4: Section 1 - Data Communications Overview | D4: 1.3 | E4: Serial vs parallel; protocol, mark/space, BPS vs baud, CPS | F4: Not Started | G4: 1 | H4: 3 | I4: coursepacks/CMTC2341/Content/CP#1400 - CMTC 2341.pdf | J4: 4 | K4: 1.5
A5: 4 | B5: 1 | C5: Section 1 - Data Communications Overview | D5: 1.4 | E5: Simplex / half-duplex / full-duplex | F5: Not Started | G5: 1 | H5: 3 | I5: coursepacks/CMTC2341/Content/CP#1400 - CMTC 2341.pdf | J5: 5 | K5: 1.5
A6: 5 | B6: 1 | C6: Section 1 - Data Communications Overview | D6: 1.5 | E6: Asynchronous serial framing: start/stop bits, parity (incl. stick parity) | F6: Not Started | G6: 1 | H6: 3 | I6: coursepacks/CMTC2341/Content/CP#1400 - CMTC 2341.pdf | J6: 6 | K6: 1.5
A7: 6 | B7: 1 | C7: Section 1 - Data Communications Overview | D7: 1.6 | E7: Electrical characteristics & UART transmitter block diagram | F7: Not Started | G7: 1 | H7: 3 | I7: coursepacks/CMTC2341/Content/CP#1400 - CMTC 2341.pdf | J7: 10 | K7: 1.5
A8: 7 | B8: 1 | C8: Section 2 - EIA/TIA Standards | D8: 2.1 | E8: RS-232 electrical characteristics (voltage levels, noise margin) | F8: Not Started | G8: 1 | H8: 3 | I8: coursepacks/CMTC2341/Content/CP#1400 - CMTC 2341.pdf | J8: 13 | K8: 1.5
A9: 8 | B9: 1 | C9: Section 2 - EIA/TIA Standards | D9: 2.2 | E9: RS-232 mechanical characteristics: DB-25/DB-9 pinouts, handshake signals | F9: Not Started | G9: 1 | H9: 3 | I9: coursepacks/CMTC2341/Content/CP#1400 - CMTC 2341.pdf | J9: 15 | K9: 1.5
A10: 9 | B10: 1 | C10: Section 2 - EIA/TIA Standards | D10: 2.3 | E10: Transmission line systems: unbalanced vs balanced | F10: Not Started | G10: 1 | H10: 3 | I10: coursepacks/CMTC2341/Content/CP#1400 - CMTC 2341.pdf | J10: 17 | K10: 1.5
A11: 10 | B11: 1 | C11: Section 2 - EIA/TIA Standards | D11: 2.4 | E11: RS-422 / RS-485 balanced transmission, termination, multidrop | F11: Not Started | G11: 1 | H11: 3 | I11: coursepacks/CMTC2341/Content/CP#1400 - CMTC 2341.pdf | J11: 18 | K11: 1.5
A12: 11 | B12: 1 | C12: Section 2 - EIA/TIA Standards | D12: 2.5 | E12: RS-423 | F12: Not Started | G12: 1 | H12: 3 | I12: coursepacks/CMTC2341/Content/CP#1400 - CMTC 2341.pdf | J12: 24 | K12: 1.5
A13: 12 | B13: 1 | C13: Section 2 - EIA/TIA Standards | D13: 2.6 | E13: EIA standard comparison table | F13: Not Started | G13: 1 | H13: 3 | I13: coursepacks/CMTC2341/Content/CP#1400 - CMTC 2341.pdf | J13: 25 | K13: 1.5
... A51: 50 | B51: 1 | C51: Section 8 - Introduction to Modicon PLCs | D51: 8.5 | E51: MOVE, LD representation, basic math functions | F51: Not Started | G51: 1 | H51: 3 | I51: coursepacks/CMTC2341/Content/CP#1400 - CMTC 2341.pdf | J51: 176 | K51: 1.5
A52: 51 | B52: 2 | C52: Section 1 - Basic Control Loop | D52: 1.1 | E52: Introduction to process control | F52: Not Started | G52: 1 | H52: 3 | I52: coursepacks/CNTR2371/01 - Section 1 - Basic Control Loop.pdf | J52: 5 | K52: 1.5 | N52: coursepack page 1.1
A53: 52 | B53: 2 | C53: Section 1 - Basic Control Loop | D53: 1.1.1 | E53: Feedback vs feedforward control strategies | F53: Not Started | G53: 1 | H53: 3 | I53: coursepacks/CNTR2371/01 - Section 1 - Basic Control Loop.pdf | J53: 8 | K53: 1.5 | N53: coursepack page 1.4
A54: 53 | B54: 2 | C54: Section 1 - Basic Control Loop | D54: 1.1.2 | E54: History of process control | F54: Not Started | G54: 1 | H54: 3 | I54: coursepacks/CNTR2371/01 - Section 1 - Basic Control Loop.pdf | J54: 14 | K54: 1.5 | N54: coursepack page 1.10
A55: 54 | B55: 2 | C55: Section 1 - Basic Control Loop | D55: 1.1.3 | E55: Review of P&ID symbol standards | F55: Not Started | G55: 1 | H55: 3 | I55: coursepacks/CNTR2371/01 - Section 1 - Basic Control Loop.pdf | J55: 19 | K55: 1.5 | N55: coursepack page 1.15
A56: 55 | B56: 2 | C56: Section 1 - Basic Control Loop | D56: 1.1.4 | E56: Measurement terminology | F56: Not Started | G56: 1 | H56: 3 | I56: coursepacks/CNTR2371/01 - Section 1 - Basic Control Loop.pdf | J56: 21 | K56: 1.5 | N56: coursepack page 1.17
A57: 56 | B57: 2 | C57: Section 1 - Basic Control Loop | D57: 1.1.5 | E57: Letter symbols | F57: Not Started | G57: 1 | H57: 3 | I57: coursepacks/CNTR2371/01 - Section 1 - Basic Control Loop.pdf | J57: 24 | K57: 1.5 | N57: coursepack page 1.20
A58: 57 | B58: 2 | C58: Section 1 - Basic Control Loop | D58: 1.1.6 | E58: Questions (1.1) | F58: Not Started | G58: 1 | H58: 3 | I58: coursepacks/CNTR2371/01 - Section 1 - Basic Control Loop.pdf | J58: 25 | K58: 1.5 | N58: coursepack page 1.21
A59: 58 | B59: 2 | C59: Section 1 - Basic Control Loop | D59: 1.2 | E59: Feedback control loop components - the four standard components | F59: Not Started | G59: 1 | H59: 3 | I59: coursepacks/CNTR2371/01 - Section 1 - Basic Control Loop.pdf | J59: 29 | K59: 1.5 | N59: coursepack page 1.25
A60: 59 | B60: 2 | C60: Section 1 - Basic Control Loop | D60: 1.2.2 | E60: Questions (1.2) | F60: Not Started | G60: 1 | H60: 3 | I60: coursepacks/CNTR2371/01 - Section 1 - Basic Control Loop.pdf | J60: 34 | K60: 1.5 | N60: coursepack page 1.30
A61: 60 | B61: 2 | C61: Section 1 - Basic Control Loop | D61: 1.3 | E61: Block diagram algebra: flow, summing, branching | F61: Not Started | G61: 1 | H61: 3 | I61: coursepacks/CNTR2371/01 - Section 1 - Basic Control Loop.pdf | J61: 37 | K61: 1.5 | N61: coursepack page 1.33
A62: 61 | B62: 2 | C62: Section 1 - Basic Control Loop | D62: 1.3.4 | E62: Block diagram reductions | F62: Not Started | G62: 1 | H62: 3 | I62: coursepacks/CNTR2371/01 - Section 1 - Basic Control Loop.pdf | J62: 39 | K62: 1.5 | N62: coursepack page 1.35
A63: 62 | B63: 2 | C63: Section 1 - Basic Control Loop | D63: 1.3.5 | E63: Questions (1.3) | F63: Not Started | G63: 1 | H63: 3 | I63: coursepacks/CNTR2371/01 - Section 1 - Basic Control Loop.pdf | J63: 45 | K63: 1.5 | N63: coursepack page 1.41
... A203: 202 | B203: 4 | C203: Section 6 - RSLogix Sequential Function Charts (SFC) | D203: 6.9 | E203: Practice worksheet: batch control, kiln control | F203: Not Started | G203: 1 | H203: 3 | I203: coursepacks/INST2340/06 - Section 6 - RSLogix Sequential Function Charts (SFC).pdf | J203: 32 | K203: 1.5 | N203: coursepack page 6-30
A204: 203 | B204: 5 | C204: Section 1 - Introduction to Instrumentation Engineering and Design | D204: 1.1 | E204: Instrumentation engineering scope, credentials, professional ethics | F204: Not Started | G204: 1 | H204: 3 | I204: coursepacks/INST2361/Coursepack Files/Lecture Coursepack Files/01 - Introduction to Instrumentation Engineering and Design.pdf | K204: 1.5
A205: 204 | B205: 5 | C205: Section 1 - Introduction to Instrumentation Engineering and Design | D205: 1.2 | E205: Industry standards, specifications, permits, hazardous area classification | F205: Not Started | G205: 1 | H205: 3 | I205: coursepacks/INST2361/Coursepack Files/Lecture Coursepack Files/01 - Introduction to Instrumentation Engineering and Design.pdf | K205: 1.5
A206: 205 | B206: 5 | C206: Section 1 - Introduction to Instrumentation Engineering and Design | D206: 1.3 | E206: Core skills of an instrument designer | F206: Not Started | G206: 1 | H206: 3 | I206: coursepacks/INST2361/Coursepack Files/Lecture Coursepack Files/01 - Introduction to Instrumentation Engineering and Design.pdf | K206: 1.5
A207: 206 | B207: 5 | C207: Section 2 - Introduction to Projects and Project Management | D207: 2.1 | E207: Project features, terminology, key participants, phases | F207: Not Started | G207: 1 | H207: 3 | I207: coursepacks/INST2361/Coursepack Files/Lecture Coursepack Files/02 - Introduction to Projects and Project Management (2026-05-21).pdf | K207: 1.5
A208: 207 | B208: 5 | C208: Section 2 - Introduction to Projects and Project Management | D208: 2.2 | E208: The bid process (steps 1-7); types of contracts | F208: Not Started | G208: 1 | H208: 3 | I208: coursepacks/INST2361/Coursepack Files/Lecture Coursepack Files/02 - Introduction to Projects and Project Management (2026-05-21).pdf | K208: 1.5
A209: 208 | B209: 5 | C209: Section 2 - Introduction to Projects and Project Management | D209: 2.3 | E209: Project management: PM roles, project controls, kickoff meeting | F209: Not Started | G209: 1 | H209: 3 | I209: coursepacks/INST2361/Coursepack Files/Lecture Coursepack Files/02 - Introduction to Projects and Project Management (2026-05-21).pdf | K209: 1.5
A210: 209 | B210: 5 | C210: Section 3 - Project Scheduling | D210: 3.1 | E210: Work breakdown structure & task list | F210: Not Started | G210: 1 | H210: 3 | I210: coursepacks/INST2361/Coursepack Files/Lecture Coursepack Files/03 - Project Scheduling (2026-05-21).pdf | K210: 1.5
A211: 210 | B211: 5 | C211: Section 3 - Project Scheduling | D211: 3.3 | E211: Network / precedence diagram; forward & backward pass | F211: Not Started | G211: 1 | H211: 3 | I211: coursepacks/INST2361/Coursepack Files/Lecture Coursepack Files/03 - Project Scheduling (2026-05-21).pdf | K211: 1.5
A212: 211 | B212: 5 | C212: Section 3 - Project Scheduling | D212: 3.4 | E212: Task relationships: FS, SS, FF, SF | F212: Not Started | G212: 1 | H212: 3 | I212: coursepacks/INST2361/Coursepack Files/Lecture Coursepack Files/03 - Project Scheduling (2026-05-21).pdf | K212: 1.5
A213: 212 | B213: 5 | C213: Section 3 - Project Scheduling | D213: 3.5 | E213: Gantt chart (MS Project symbols) | F213: Not Started | G213: 1 | H213: 3 | I213: coursepacks/INST2361/Coursepack Files/Lecture Coursepack Files/03 - Project Scheduling (2026-05-21).pdf | K213: 1.5
A214: 213 | B214: 5 | C214: Section 3 - Project Scheduling | D214: 3.6 | E214: Scheduling exercises | F214: Not Started | G214: 1 | H214: 3 | I214: coursepacks/INST2361/Coursepack Files/Lecture Coursepack Files/03 - Project Scheduling (2026-05-21).pdf | K214: 1.5
A215: 214 | B215: 5 | C215: Section 4 - Project Cost Estimates | D215: 4.1 | E215: Estimate types; detailed estimates | F215: Not Started | G215: 1 | H215: 3 | I215: coursepacks/INST2361/Coursepack Files/Lecture Coursepack Files/04 - Project Cost Estimates (2026-05-21).pdf | K215: 1.5
... A224: 223 | B224: 5 | C224: Section 6 - Natural Gas (NOT IN EXPORT) + Appendix A | D224: A.2 | E224: Gas absorption basics & operation | F224: Not Started | G224: 1 | H224: 3 | I224: coursepacks/INST2361/Coursepack Files/Lecture Coursepack Files/06A - Adsorption and absoprtion.pdf | K224: 1.5
...

Sheet Assessments
A1: assessment_id | B1: course_id | C1: type | D1: title | E1: category | F1: due_date | G1: due_time | H1: location | I1: status | J1: score | K1: max_score | L1: weight_override | M1: topic_ids | N1: estimated_hours | O1: notes
A2: 1 | B2: 1 | C2: Midterm | D2: Theory Assessment #1 (Outcomes 1-2: serial comms, protocol analysis) | E2: Theory Assessment 1 | F2: 2026-09-23 | H2: lecture room | I2: Not Started | K2: 100 | M2: 1,2,3,4,5,6,7,8,9,10,11,12,13,14,15,16,17,18 | N2: 8 | O2: CONFLICT: evaluation table says week of Sep 23 (wk 4); weekly schedule shows wk 6 (Oct 5-9). Confirm on Brightspace. Earlier date used.
A3: 2 | B3: 1 | C3: Midterm | D3: Theory Assessment #2 (Outcome 3: transmission media) | E3: Theory Assessment 2 | F3: 2026-10-14 | H3: lecture room | I3: Not Started | K3: 100 | M3: 19,20,21,22,23,24,25,26,27,28,29 | N3: 6 | O3: CONFLICT: evaluation table says week of Oct 14 (wk 7); weekly schedule shows wk 10 (Nov 2-6). Confirm. Earlier date used.
A4: 3 | B4: 1 | C4: Final | D4: Theory Assessment #3 (Outcomes 4-5: networks/OSI, security) | E4: Theory Assessment 3 | F4: 2026-12-09 | H4: lecture room | I4: Not Started | K4: 100 | M4: 30,31,32,33,34,35,36,37,38,39,40,41,42,43,44,45,46,47,48,49,50 | N4: 10 | O4: Week of Dec 9 (wk 15). Exact day TBC.
A5: 4 | B5: 2 | C5: Midterm | D5: Theory Assessment 1 (Sections 1-3) | E5: Theory Assessment 1 | F5: 2026-10-06 | H5: lecture room | I5: Not Started | K5: 100 | M5: 51,52,53,54,55,56,57,58,59,60,61,62,63,64,65,66,67,68,69,70,71,72,73,74,75,76,77,78,79 | N5: 10 | O5: Week 6 (Oct 5-9). Exact day TBC - lectures Tue/Wed/Thu.
A6: 5 | B6: 2 | C6: Practical Lab Assessment | D6: Practical In-Lab Assessment 1 | E6: Practical In-Lab Assessment 1 | F6: 2026-10-06 | G6: 08:00 | H6: Y136 | I6: Not Started | K6: 100 | M6: 51,52,53,54,55,56,57,58,59,60,61,62,63,64,65,66,67,68,69,70,71,72,73,74,75,76,77,78,79 | N6: 4 | O6: X01/X02 week of Oct 5 per syllabus schedule (eval table: week 5 or 6). Covers Labs 01-04 (PAC 353 + plant characteristics).
A7: 6 | B7: 2 | C7: Midterm | D7: Theory Assessment 2 (Sections 4-5) | E7: Theory Assessment 2 | F7: 2026-10-27 | H7: lecture room | I7: Not Started | K7: 100 | M7: 80,81,82,83,84,85,86,87,88,89,90,91,92 | N7: 10 | O7: CONFLICT: evaluation table says week 9 (Oct 26-30); weekly schedule lists it under Nov 2 week (wk 10). Confirm. Earlier date used.
A8: 7 | B8: 2 | C8: Practical Lab Assessment | D8: Practical In-Lab Assessment 2 | E8: Practical In-Lab Assessment 2 | F8: 2026-11-03 | G8: 08:00 | H8: Y136 | I8: Not Started | K8: 100 | M8: 80,81,82,83,84,85,86,87,88,89,90,91,92,93,94 | N8: 4 | O8: X01/X02 week of Nov 2 per syllabus. Covers Labs 05-07 (stability, tuning).
A9: 8 | B9: 2 | C9: Final | D9: Theory Assessment 3 (Sections 6-8) | E9: Theory Assessment 3 | F9: 2026-12-14 | H9: TBC | I9: Not Started | K9: 100 | M9: 93,94,95,96,97,98,99,100,101,102,103,104,105,106,107,108,109 | N9: 12 | O9: Week 16 exam week (Dec 14-16). Exact day TBC.
A10: 9 | B10: 3 | C10: Midterm | D10: Midterm #1 (Section 1 - Accuracy) | E10: Midterm 1 | F10: 2026-09-28 | H10: lecture room | I10: Not Started | K10: 100 | M10: 110,111,112,113,114,115,116,117,118,119 | N10: 8 | O10: Week of Sep 28. Exact day TBC (lectures Mon/Wed/Thu).
A11: 10 | B11: 3 | C11: Practical Lab Assessment | D11: Lab Practical Assessment #1 (Labs 1-4) | E11: Practical Assessment 1 | F11: 2026-10-19 | G11: 08:00 | H11: Y205 | I11: Not Started | K11: 100 | M11: 110,111,112,113,114,115,116,117,118,119,120,121,122,123,124,125,126,127,128,129 | N11: 4 | O11: Syllabus: ~week 7. X02 Monday of wk 7 = Oct 12 (Thanksgiving). Inferred Oct 19 - check Brightspace lab exam schedule.
A12: 11 | B12: 3 | C12: Midterm | D12: Midterm #2 (Sections 2-3 - velocity, volumetric, mass flow) | E12: Midterm 2 | F12: 2026-11-02 | H12: lecture room | I12: Not Started | K12: 100 | M12: 120,121,122,123,124,125,126,127,128,129,130,131,132,133,134,135,136,137,138 | N12: 10 | O12: Week of Nov 2. Exact day TBC.
A13: 12 | B13: 3 | C13: Practical Lab Assessment | D13: Lab Practical Assessment #2 (Labs 5-10) | E13: Practical Assessment 2 | F13: 2026-12-14 | G13: 08:00 | H13: Y205 | I13: Not Started | K13: 100 | M13: 120,121,122,123,124,125,126,127,128,129,130,131,132,133,134,135,136,137,138,150,151,152,153,154,155,156,157,158,159 | N13: 4 | O13: Syllabus: ~week 15. Inferred X02 Monday Dec 14 after 6 rotation labs - check Brightspace lab exam schedule.
A14: 13 | B14: 3 | C14: Final | D14: Final (Sections 4-6 - industrial requirements, density, tank gauging) | E14: Final | F14: 2026-12-14 | H14: TBC | I14: Not Started | K14: 100 | M14: 139,140,141,142,143,144,145,146,147,148,149,150,151,152,153,154,155,156,157,158,159 | N14: 12 | O14: Week of Dec 14. Exact day TBC.
A15: 14 | B15: 4 | C15: Midterm | D15: Exam #1 (Outcomes 1-2: PLC intro, hardware, LD basics) | E15: Exam 1 | F15: 2026-09-29 | H15: lecture room | I15: Not Started | K15: 100 | M15: 160,161,162,163,164,165,166,167,168,169,170,171,172,173,174,175,176,177,178,179 | N15: 8 | O15: Weekly schedule: week 5 (Sep 28-Oct 2; no class Wed Sep 30). Evaluation table says TBD. Confirm.
A16: 15 | B16: 4 | C16: Practical Lab Assessment | D16: Practical In-Lab Assessment #1 [LD] | E16: Labs & Practical In-Lab Assessments | F16: 2026-10-22 | G16: 08:00 | H16: Y238 | I16: Not Started | K16: 100 | M16: 172,173,174,175,176,177,178,179 | N16: 4 | O16: Week 8. Covers weekly labs to date (LD). Second X02 session Fri Oct 23.
A17: 16 | B17: 4 | C17: Project | D17: Lab Project - differential gap level control + Node-RED HMI + MQTT (HiveMQ) | E17: Lab Project | F17: 2026-12-11 | H17: Y238 | I17: Not Started | K17: 100 | M17: 172,173,174,175,176,177,178,179,180,181,182,183,184,185,186,187,188,189,190,191,192,193,194,195,196,197,198,199,200,201,202 | N17: 15 | O17: Info given week 7, overview week 9, milestones announced then. Final due date TBC - placeholder end of week 15. Needs HiveMQ account; see Lab 19 Node-RED & Lab 20 MQTT.
A18: 17 | B18: 4 | C18: Midterm | D18: Exam #2 (Outcomes 3-4: LD advanced, FBD) | E18: Exam 2 | F18: 2026-11-10 | H18: lecture room | I18: Not Started | K18: 100 | M18: 172,173,174,175,176,177,178,179,180,181,182,183,184,185,186,187,188 | N18: 8 | O18: Weekly schedule: week 11 (Nov 9-13; no classes Nov 11-13 so likely Mon/Tue). Evaluation table says TBD. Confirm.
A19: 18 | B19: 4 | C19: Practical Lab Assessment | D19: Practical In-Lab Assessment #2 (FBD, SFC, ST) | E19: Labs & Practical In-Lab Assessments | F19: 2026-12-03 | G19: 08:00 | H19: Y238 | I19: Not Started | K19: 100 | M19: 180,181,182,183,184,185,186,187,188,189,190,191,192,193,194,195,196,197,198,199,200,201,202 | N19: 4 | O19: Week 14. Second X02 session Fri Dec 4.
A20: 19 | B20: 4 | C20: Final | D20: Exam #3 (Outcomes 5-7: ST, SFC) | E20: Exam 3 | F20: 2026-12-08 | H20: lecture room | I20: Not Started | K20: 100 | M20: 189,190,191,192,193,194,195,196,197,198,199,200,201,202 | N20: 10 | O20: Weekly schedule: week 15 (Dec 7-11). Evaluation table says TBD. Confirm.
A21: 20 | B21: 6 | C21: Quiz | D21: Brightspace Orientation Questions (before first in-person lab) | E21: Pre-lab quizzes & orientation | F21: 2026-09-08 | G21: 13:45 | H21: Brightspace | I21: Not Started | K21: 100 | M21: 241,242,243,244,245,246,247 | N21: 1 | O21: Required before first lab (F2025 lab syllabus). If your first lab was Sep 1, mark Submitted.

Sheet PreLabs
A1: prelab_id | B1: course_id | C1: lab_number | D1: title | E1: lab_type | F1: lab_date | G1: lab_time | H1: room | I1: prelab_due | J1: checklist | K1: link | L1: completed | M1: completed_on | N1: notes
A2: 1 | B2: 1 | C2: 1 | D2: Lab 1 - Introduction to Serial Data Communication (RS-232, break-out box, oscilloscope frames, null-modem, radio modems) | E2: Common | F2: 2026-09-04 | G2: 08:00 | H2: Y237 | I2: 2026-09-03 | J2: [ ] Read the lab section in CP#1400|[ ] Answer pre-lab questions in the lab (if any)|[ ] Bring memory stick | K2: coursepacks/CMTC2341/Content/CP#1400 - CMTC 2341.pdf#page=183 | L2: FALSE | N2: Pre-lab questions on CP#1400 p215. INFERRED lab-to-date mapping (portal X02 dates; syllabus lab list in order). Confirm on Brightspace.
A3: 2 | B3: 1 | C3: 2 | D3: Lab 2 - DGH Smart Transmitters (RS-232 commands, checksums, daisy-chain network) | E3: Common | F3: 2026-09-18 | G3: 08:00 | H3: Y237 | I3: 2026-09-17 | J3: [ ] Read the lab section in CP#1400|[ ] Answer pre-lab questions in the lab (if any)|[ ] Bring memory stick | K3: coursepacks/CMTC2341/Content/CP#1400 - CMTC 2341.pdf#page=221 | L3: FALSE | N3: Pre-lab table on CP#1400 p223. INFERRED lab-to-date mapping (portal X02 dates; syllabus lab list in order). Confirm on Brightspace.
A4: 3 | B4: 1 | C4: 3 | D4: Lab 3 - Ethernet Cables and Remote Connectivity | E4: Common | F4: 2026-10-02 | G4: 08:00 | H4: Y237 | I4: 2026-10-01 | J4: [ ] Read the lab section in CP#1400|[ ] Answer pre-lab questions in the lab (if any)|[ ] Bring memory stick | K4: coursepacks/CMTC2341/Content/CP#1400 - CMTC 2341.pdf#page=249 | L4: FALSE | N4: INFERRED lab-to-date mapping (portal X02 dates; syllabus lab list in order). Confirm on Brightspace.
A5: 4 | B5: 1 | C5: 4 | D5: Lab 4 - Network Devices (hubs/switches/routers, ping, telnet) | E5: Common | F5: 2026-10-16 | G5: 08:00 | H5: Y237 | I5: 2026-10-15 | J5: [ ] Read the lab section in CP#1400|[ ] Answer pre-lab questions in the lab (if any)|[ ] Bring memory stick | K5: coursepacks/CMTC2341/Content/CP#1400 - CMTC 2341.pdf#page=261 | L5: FALSE | N5: Pre-lab questions on CP#1400 p263. INFERRED lab-to-date mapping (portal X02 dates; syllabus lab list in order). Confirm on Brightspace.
A6: 5 | B6: 1 | C6: 5 | D6: Lab 5 - Ethernet Networks - Packet Tracer / Wireshark | E6: Common | F6: 2026-10-30 | G6: 08:00 | H6: Y237 | I6: 2026-10-29 | J6: [ ] Read the lab section in CP#1400|[ ] Answer pre-lab questions in the lab (if any)|[ ] Bring memory stick | K6: coursepacks/CMTC2341/Content/CP#1400 - CMTC 2341.pdf#page=277 | L6: FALSE | N6: Pre-Lab Work on CP#1400 p280. INFERRED lab-to-date mapping (portal X02 dates; syllabus lab list in order). Confirm on Brightspace.
A7: 6 | B7: 1 | C7: 6 | D7: Lab 6 - Quantum PLC Intro (Modicon / Unity) | E7: Common | F7: 2026-11-27 | G7: 08:00 | H7: Y237 | I7: 2026-11-26 | J7: [ ] Read the lab section in CP#1400|[ ] Answer pre-lab questions in the lab (if any)|[ ] Bring memory stick | K7: coursepacks/CMTC2341/Content/CP#1400 - CMTC 2341.pdf#page=289 | L7: FALSE | N7: INFERRED lab-to-date mapping (portal X02 dates; syllabus lab list in order). Confirm on Brightspace.
A8: 7 | B8: 1 | C8: 7 | D8: Lab 7 - Wireless Transmitters / Firewalls (Cisco PT) - Modbus TCP | E8: Common | F8: 2026-12-11 | G8: 08:00 | H8: Y237 | I8: 2026-12-10 | J8: [ ] Read the lab section in CP#1400|[ ] Answer pre-lab questions in the lab (if any)|[ ] Bring memory stick | K8: coursepacks/CMTC2341/Content/CP#1400 - CMTC 2341.pdf#page=301 | L8: FALSE | N8: Pre-Lab Work on CP#1400 p303. INFERRED lab-to-date mapping (portal X02 dates; syllabus lab list in order). Confirm on Brightspace.
A9: 8 | B9: 1 | C9: - | D9: NO LAB - Fall Break (X02 session lost per syllabus) | E9: None | F9: 2026-11-13 | G9: 08:00 | H9: Y237 | I9: 2026-11-12 | J9: [ ] Read the lab section in CP#1400|[ ] Answer pre-lab questions in the lab (if any)|[ ] Bring memory stick | L9: TRUE
A10: 9 | B10: 2 | C10: Intro | D10: Lab Introduction and Familiarization | E10: Common | F10: 2026-09-01 | G10: 08:00 | H10: Y136 | I10: 2026-08-31 | J10: [ ] Read the lab Theory section|[ ] Answer LABORATORY PREPARATION questions (individually)|[ ] Print/bring Results sheet|[ ] Safety glasses, closed-toe shoes, instrument screwdriver | K10: coursepacks/CNTR2371_LAB/00 - CNTR2371 Lab Overview.pdf | L10: FALSE | N10: Week 1 (already happened - tick if done)
A11: 10 | B11: 2 | C11: 01C | D11: Siemens PAC 353 Configuration II | E11: Common | F11: 2026-09-08 | G11: 08:00 | H11: Y136 | I11: 2026-09-07 | J11: [ ] Read the lab Theory section|[ ] Answer LABORATORY PREPARATION questions (individually)|[ ] Print/bring Results sheet|[ ] Safety glasses, closed-toe shoes, instrument screwdriver | K11: coursepacks/CNTR2371_LAB/01 - Lab 01C -Siemens PAC 353 Configuration II (Theory and Procedure).pdf | L11: FALSE | N11: Pre-lab = 'Laboratory Preparation' PDF (16 questions on SETPT/PID/A/M/ODC/AOUT1 blocks)
A12: 11 | B12: 2 | C12: 02C | D12: Siemens PAC 353 Operation | E12: Common | F12: 2026-09-15 | G12: 08:00 | H12: Y136 | I12: 2026-09-14 | J12: [ ] Read the lab Theory section|[ ] Answer LABORATORY PREPARATION questions (individually)|[ ] Print/bring Results sheet|[ ] Safety glasses, closed-toe shoes, instrument screwdriver | K12: coursepacks/CNTR2371_LAB/02 - Lab 02C - Siemens PAC 353 Operation (Theory_Procedure).pdf | L12: FALSE
A13: 12 | B13: 2 | C13: 03C | D13: Plant Characteristics I (The 3 Basic Plants) | E13: Common | F13: 2026-09-22 | G13: 08:00 | H13: Y136 | I13: 2026-09-21 | J13: [ ] Read the lab Theory section|[ ] Answer LABORATORY PREPARATION questions (individually)|[ ] Print/bring Results sheet|[ ] Safety glasses, closed-toe shoes, instrument screwdriver | K13: coursepacks/CNTR2371_LAB/03 - Lab 03C - Plant Characteristics I (The 3 Basic Plants) (Theory_Procedure).pdf | L13: FALSE
A14: 13 | B14: 2 | C14: 04C | D14: Plant Characteristics II (Multicapacity Plants) | E14: Common | F14: 2026-09-29 | G14: 08:00 | H14: Y136 | I14: 2026-09-28 | J14: [ ] Read the lab Theory section|[ ] Answer LABORATORY PREPARATION questions (individually)|[ ] Print/bring Results sheet|[ ] Safety glasses, closed-toe shoes, instrument screwdriver | K14: coursepacks/CNTR2371_LAB/04 - Lab 04C - Plant Characteristics II (Multicapacity Plants) (Theory_Procedure).pdf | L14: FALSE
A15: 14 | B15: 2 | C15: PILA1 | D15: Practical In-Lab Assessment 1 (7.5%) | E15: Assessment | F15: 2026-10-06 | G15: 08:00 | H15: Y136 | I15: 2026-10-05 | J15: [ ] Read the lab Theory section|[ ] Answer LABORATORY PREPARATION questions (individually)|[ ] Print/bring Results sheet|[ ] Safety glasses, closed-toe shoes, instrument screwdriver | L15: FALSE | N15: Review Labs 01-04; 50 min; see Assessments
A16: 15 | B16: 2 | C16: 05C | D16: Control Loop Stability | E16: Common | F16: 2026-10-13 | G16: 08:00 | H16: Y136 | I16: 2026-10-12 | J16: [ ] Read the lab Theory section|[ ] Answer LABORATORY PREPARATION questions (individually)|[ ] Print/bring Results sheet|[ ] Safety glasses, closed-toe shoes, instrument screwdriver | K16: coursepacks/CNTR2371_LAB/05 - Lab 05C - Control Loop Stability (Theory_Procedure).pdf | L16: FALSE | N16: Week 7 (Mon Oct 12 Thanksgiving; Tue lab runs per syllabus)
A17: 16 | B17: 2 | C17: 06C | D17: Trial and Error Tuning Methods | E17: Common | F17: 2026-10-20 | G17: 08:00 | H17: Y136 | I17: 2026-10-19 | J17: [ ] Read the lab Theory section|[ ] Answer LABORATORY PREPARATION questions (individually)|[ ] Print/bring Results sheet|[ ] Safety glasses, closed-toe shoes, instrument screwdriver | K17: coursepacks/CNTR2371_LAB/06 - Lab 06C - Trial and Error Tuning Methods (Theory_Procedure).pdf | L17: FALSE | N17: Syllabus row says 'Lab 06 - Control Loop Stability' but Lab 06 = Trial and Error Tuning
A18: 17 | B18: 2 | C18: 07C | D18: Ziegler-Nichols Tuning Methods | E18: Common | F18: 2026-10-27 | G18: 08:00 | H18: Y136 | I18: 2026-10-26 | J18: [ ] Read the lab Theory section|[ ] Answer LABORATORY PREPARATION questions (individually)|[ ] Print/bring Results sheet|[ ] Safety glasses, closed-toe shoes, instrument screwdriver | K18: coursepacks/CNTR2371_LAB/07 - Lab 07C - Ziegler-Nichols Tuning Methods (Theory_Procedure).pdf | L18: FALSE
A19: 18 | B19: 2 | C19: PILA2 | D19: Practical In-Lab Assessment 2 (7.5%) | E19: Assessment | F19: 2026-11-03 | G19: 08:00 | H19: Y136 | I19: 2026-11-02 | J19: [ ] Read the lab Theory section|[ ] Answer LABORATORY PREPARATION questions (individually)|[ ] Print/bring Results sheet|[ ] Safety glasses, closed-toe shoes, instrument screwdriver | L19: FALSE | N19: Review Labs 05-07; see Assessments
A20: 19 | B20: 2 | C20: - | D20: NO LAB (X01/X02) - Remembrance Day / Fall Break week | E20: None | F20: 2026-11-10 | G20: 08:00 | H20: Y136 | I20: 2026-11-09 | J20: [ ] Read the lab Theory section|[ ] Answer LABORATORY PREPARATION questions (individually)|[ ] Print/bring Results sheet|[ ] Safety glasses, closed-toe shoes, instrument screwdriver | L20: TRUE | N20: No lab this week
A21: 20 | B21: 2 | C21: 08R1/09R1/10R1 | D21: Rotational lab - HE Station / Mixing Station / Pressure Vessel (order per Brightspace) | E21: Rotational | F21: 2026-11-17 | G21: 08:00 | H21: Y136 | I21: 2026-11-16 | J21: [ ] Read the lab Theory section|[ ] Answer LABORATORY PREPARATION questions (individually)|[ ] Print/bring Results sheet|[ ] Safety glasses, closed-toe shoes, instrument screwdriver | K21: coursepacks/CNTR2371_LAB | L21: FALSE | N21: Rotation order not in export - check Brightspace. Prep the one you're assigned.
A22: 21 | B22: 2 | C22: 08R1/09R1/10R1 | D22: Rotational lab - HE Station / Mixing Station / Pressure Vessel (order per Brightspace) | E22: Rotational | F22: 2026-11-24 | G22: 08:00 | H22: Y136 | I22: 2026-11-23 | J22: [ ] Read the lab Theory section|[ ] Answer LABORATORY PREPARATION questions (individually)|[ ] Print/bring Results sheet|[ ] Safety glasses, closed-toe shoes, instrument screwdriver | K22: coursepacks/CNTR2371_LAB | L22: FALSE | N22: Rotation order not in export - check Brightspace. Prep the one you're assigned.
A23: 22 | B23: 2 | C23: 08R1/09R1/10R1 | D23: Rotational lab - HE Station / Mixing Station / Pressure Vessel (order per Brightspace) | E23: Rotational | F23: 2026-12-01 | G23: 08:00 | H23: Y136 | I23: 2026-11-30 | J23: [ ] Read the lab Theory section|[ ] Answer LABORATORY PREPARATION questions (individually)|[ ] Print/bring Results sheet|[ ] Safety glasses, closed-toe shoes, instrument screwdriver | K23: coursepacks/CNTR2371_LAB | L23: FALSE | N23: Rotation order not in export - check Brightspace. Prep the one you're assigned.
A24: 23 | B24: 2 | C24: 11C | D24: Plant Frequency Response (Multicapacity Plants) | E24: Common | F24: 2026-12-08 | G24: 08:00 | H24: Y136 | I24: 2026-12-07 | J24: [ ] Read the lab Theory section|[ ] Answer LABORATORY PREPARATION questions (individually)|[ ] Print/bring Results sheet|[ ] Safety glasses, closed-toe shoes, instrument screwdriver | K24: coursepacks/CNTR2371_LAB/11 - Lab 11C -Plant Frequency Response (Multicapacity Plants) (Theory_Procedure).pdf | L24: FALSE | N24: Pre-lab = 'Laboratory Preparation' PDF
A25: 24 | B25: 3 | C25: 01C | D25: Review of Wiring Practices and Troubleshooting | E25: Common | F25: 2026-09-14 | G25: 08:00 | H25: Y205 | I25: 2026-09-13 | J25: [ ] Read lab theory + manufacturer manual|[ ] Complete LABORATORY PREPARATION questions|[ ] Safety glasses, closed-toe shoes | K25: coursepacks/INST2310/01 - Lab 01C - Review of Wiring Practices and Troubleshooting.pdf | L25: FALSE | N25: INFERRED sequence: X02 has no Monday session in wk1/wk2 (term starts Tue; Labour Day). Confirm on Brightspace.
A26: 25 | B26: 3 | C26: 02C | D26: Fluke 754 Documenting Calibrator & AMS Device Manager | E26: Common | F26: 2026-09-21 | G26: 08:00 | H26: Y205 | I26: 2026-09-20 | J26: [ ] Read lab theory + manufacturer manual|[ ] Complete LABORATORY PREPARATION questions|[ ] Safety glasses, closed-toe shoes | K26: coursepacks/INST2310/02 - Lab 02C - Fluke 754 Documenting Calibrator & AMS Device Manager.pdf | L26: FALSE | N26: Has Laboratory Preparation questions
A27: 26 | B27: 3 | C27: 03C | D27: Analog and Smart Pressure Transmitter Calibration | E27: Common | F27: 2026-09-28 | G27: 08:00 | H27: Y205 | I27: 2026-09-27 | J27: [ ] Read lab theory + manufacturer manual|[ ] Complete LABORATORY PREPARATION questions|[ ] Safety glasses, closed-toe shoes | K27: coursepacks/INST2310/03 - Lab 03C - Analog and Smart Pressure Transmitter Calibration.pdf | L27: FALSE | N27: Has Laboratory Preparation questions
A28: 27 | B28: 3 | C28: 04C | D28: Turbine Flow Meter with MC-III Totalizer | E28: Common | F28: 2026-10-05 | G28: 08:00 | H28: Y205 | I28: 2026-10-04 | J28: [ ] Read lab theory + manufacturer manual|[ ] Complete LABORATORY PREPARATION questions|[ ] Safety glasses, closed-toe shoes | K28: coursepacks/INST2310/04 - Lab 04C - Turbine Flow Meter with MC-III Totalizer.pdf | L28: FALSE | N28: Pre-lab: K-factor calculation etc. (Laboratory Preparation)
A29: 28 | B29: 3 | C29: - | D29: NO LAB - Thanksgiving | E29: None | F29: 2026-10-12 | G29: 08:00 | H29: Y205 | I29: 2026-10-11 | J29: [ ] Read lab theory + manufacturer manual|[ ] Complete LABORATORY PREPARATION questions|[ ] Safety glasses, closed-toe shoes | L29: TRUE
A30: 29 | B30: 3 | C30: PA1 | D30: Lab Practical Assessment #1 on Labs 1-4 (7%) | E30: Assessment | F30: 2026-10-19 | G30: 08:00 | H30: Y205 | I30: 2026-10-18 | J30: [ ] Read lab theory + manufacturer manual|[ ] Complete LABORATORY PREPARATION questions|[ ] Safety glasses, closed-toe shoes | L30: FALSE | N30: INFERRED date - syllabus says ~week 7; check Brightspace lab exam schedule
A31: 30 | B31: 3 | C31: 05R-10R | D31: Rotational lab (Radar TG / Vortex+Ultrasonic / Magnetic / Coriolis / Gas flow run / Tank gauging) - bench per Brightspace | E31: Rotational | F31: 2026-10-26 | G31: 08:00 | H31: Y205 | I31: 2026-10-25 | J31: [ ] Read lab theory + manufacturer manual|[ ] Complete LABORATORY PREPARATION questions|[ ] Safety glasses, closed-toe shoes | K31: coursepacks/INST2310 | L31: FALSE | N31: Rotation order not in export. Most rotation labs have Laboratory Preparation questions.
A32: 31 | B32: 3 | C32: 05R-10R | D32: Rotational lab (Radar TG / Vortex+Ultrasonic / Magnetic / Coriolis / Gas flow run / Tank gauging) - bench per Brightspace | E32: Rotational | F32: 2026-11-02 | G32: 08:00 | H32: Y205 | I32: 2026-11-01 | J32: [ ] Read lab theory + manufacturer manual|[ ] Complete LABORATORY PREPARATION questions|[ ] Safety glasses, closed-toe shoes | K32: coursepacks/INST2310 | L32: FALSE | N32: Rotation order not in export. Most rotation labs have Laboratory Preparation questions.
A33: 32 | B33: 3 | C33: 05R-10R | D33: Rotational lab (Radar TG / Vortex+Ultrasonic / Magnetic / Coriolis / Gas flow run / Tank gauging) - bench per Brightspace | E33: Rotational | F33: 2026-11-09 | G33: 08:00 | H33: Y205 | I33: 2026-11-08 | J33: [ ] Read lab theory + manufacturer manual|[ ] Complete LABORATORY PREPARATION questions|[ ] Safety glasses, closed-toe shoes | K33: coursepacks/INST2310 | L33: FALSE | N33: Rotation order not in export. Most rotation labs have Laboratory Preparation questions.
A34: 33 | B34: 3 | C34: 05R-10R | D34: Rotational lab (Radar TG / Vortex+Ultrasonic / Magnetic / Coriolis / Gas flow run / Tank gauging) - bench per Brightspace | E34: Rotational | F34: 2026-11-16 | G34: 08:00 | H34: Y205 | I34: 2026-11-15 | J34: [ ] Read lab theory + manufacturer manual|[ ] Complete LABORATORY PREPARATION questions|[ ] Safety glasses, closed-toe shoes | K34: coursepacks/INST2310 | L34: FALSE | N34: Rotation order not in export. Most rotation labs have Laboratory Preparation questions.
A35: 34 | B35: 3 | C35: 05R-10R | D35: Rotational lab (Radar TG / Vortex+Ultrasonic / Magnetic / Coriolis / Gas flow run / Tank gauging) - bench per Brightspace | E35: Rotational | F35: 2026-11-23 | G35: 08:00 | H35: Y205 | I35: 2026-11-22 | J35: [ ] Read lab theory + manufacturer manual|[ ] Complete LABORATORY PREPARATION questions|[ ] Safety glasses, closed-toe shoes | K35: coursepacks/INST2310 | L35: FALSE | N35: Rotation order not in export. Most rotation labs have Laboratory Preparation questions.
A36: 35 | B36: 3 | C36: 05R-10R | D36: Rotational lab (Radar TG / Vortex+Ultrasonic / Magnetic / Coriolis / Gas flow run / Tank gauging) - bench per Brightspace | E36: Rotational | F36: 2026-11-30 | G36: 08:00 | H36: Y205 | I36: 2026-11-29 | J36: [ ] Read lab theory + manufacturer manual|[ ] Complete LABORATORY PREPARATION questions|[ ] Safety glasses, closed-toe shoes | K36: coursepacks/INST2310 | L36: FALSE | N36: Rotation order not in export. Most rotation labs have Laboratory Preparation questions.
A37: 36 | B37: 3 | C37: - | D37: Practice / catch-up (syllabus wk 14 PRACTICE) | E37: Practice | F37: 2026-12-07 | G37: 08:00 | H37: Y205 | I37: 2026-12-06 | J37: [ ] Read lab theory + manufacturer manual|[ ] Complete LABORATORY PREPARATION questions|[ ] Safety glasses, closed-toe shoes | L37: FALSE
A38: 37 | B38: 3 | C38: PA2 | D38: Lab Practical Assessment #2 on Labs 5-10 (8%) | E38: Assessment | F38: 2026-12-14 | G38: 08:00 | H38: Y205 | I38: 2026-12-13 | J38: [ ] Read lab theory + manufacturer manual|[ ] Complete LABORATORY PREPARATION questions|[ ] Safety glasses, closed-toe shoes | L38: FALSE | N38: INFERRED - syllabus says ~week 15; check Brightspace lab exam schedule
A39: 38 | B39: 4 | C39: 1 | D39: CompactLogix PLC Hardware Intro and Software Template | E39: Weekly | F39: 2026-09-03 | G39: 08:00 | H39: Y238 | I39: 2026-09-02 | J39: [ ] Draft the pre-lab logic (LD/FBD/ST) on engineering paper - worth >=30% of lab mark|[ ] Answer pre-lab questions|[ ] Bring USB stick / project template | K39: coursepacks/INST2340/07 - Lab 1 - CompactLogix PLC Hardware Intro and Software Template.pdf | L39: FALSE | N39: Week 1
A40: 39 | B40: 4 | C40: 2 | D40: CompactLogix PLC Wiring and Relays | E40: Weekly | F40: 2026-09-10 | G40: 08:00 | H40: Y238 | I40: 2026-09-09 | J40: [ ] Draft the pre-lab logic (LD/FBD/ST) on engineering paper - worth >=30% of lab mark|[ ] Answer pre-lab questions|[ ] Bring USB stick / project template | K40: coursepacks/INST2340/08 - Lab 2 - CompactLogix PLC Wiring and Relays.pdf | L40: FALSE | N40: Week 2. Extra X02 session Fri Sep 11 08:00
...

Sheet Schedule
A1: schedule_id | B1: course_id | C1: kind | D1: section | E1: day_of_week | F1: start_time | G1: end_time | H1: room | I1: dates
A2: 1 | B2: 1 | C2: Lecture | D2: A01 | E2: Monday | F2: 10:00 | G2: 10:50 | H2: Y220
A3: 2 | B3: 1 | C3: Lecture | D3: A01 | E3: Thursday | F3: 14:00 | G3: 14:50 | H3: Y231
A4: 3 | B4: 1 | C4: Lecture | D4: A01 | E4: Friday | F4: 11:00 | G4: 11:50 | H4: Y202
A5: 4 | B5: 1 | C5: Lab | D5: X02 | E5: Friday | F5: 08:00 | G5: 09:50 | H5: Y237 | I5: 2026-09-04,2026-09-18,2026-10-02,2026-10-16,2026-10-30,2026-11-13,2026-11-27,2026-12-11
A6: 5 | B6: 2 | C6: Lecture | D6: A01 | E6: Tuesday | F6: 11:00 | G6: 11:50 | H6: Y202
A7: 6 | B7: 2 | C7: Lecture | D7: A01 | E7: Wednesday | F7: 10:00 | G7: 10:50 | H7: Y231
A8: 7 | B8: 2 | C8: Lecture | D8: A01 | E8: Thursday | F8: 11:00 | G8: 11:50 | H8: Y202
A9: 8 | B9: 2 | C9: Lab | D9: X02 | E9: Tuesday | F9: 08:00 | G9: 09:50 | H9: Y136
A10: 9 | B10: 3 | C10: Lecture | D10: A01 | E10: Monday | F10: 12:00 | G10: 12:50 | H10: Y202
A11: 10 | B11: 3 | C11: Lecture | D11: A01 | E11: Wednesday | F11: 11:00 | G11: 11:50 | H11: Y231
A12: 11 | B12: 3 | C12: Lecture | D12: A01 | E12: Thursday | F12: 13:00 | G12: 13:50 | H12: Y231
A13: 12 | B13: 3 | C13: Lab | D13: X02 | E13: Monday | F13: 08:00 | G13: 09:50 | H13: Y205
A14: 13 | B14: 4 | C14: Lecture | D14: A01 | E14: Tuesday | F14: 13:00 | G14: 13:50 | H14: Y233
A15: 14 | B15: 4 | C15: Lecture | D15: A01 | E15: Wednesday | F15: 13:00 | G15: 13:50 | H15: Y231
A16: 15 | B16: 4 | C16: Lecture | D16: A01 | E16: Thursday | F16: 15:00 | G16: 15:50 | H16: Y231
A17: 16 | B17: 4 | C17: Lab | D17: X02 | E17: Thursday | F17: 08:00 | G17: 09:50 | H17: Y238
A18: 17 | B18: 4 | C18: Lab | D18: X02 | E18: Friday | F18: 08:00 | G18: 09:50 | H18: Y238 | I18: 2026-09-11,2026-09-25,2026-10-09,2026-10-23,2026-11-06,2026-11-20,2026-12-04
A19: 18 | B19: 5 | C19: Lecture | D19: A01 | E19: Monday | F19: 13:00 | G19: 13:50 | H19: Y202
A20: 19 | B20: 5 | C20: Lecture | D20: A01 | E20: Thursday | F20: 10:00 | G20: 10:50 | H20: Y202
A21: 20 | B21: 5 | C21: Lecture | D21: A01 | E21: Friday | F21: 13:00 | G21: 13:50 | H21: WC312
A22: 21 | B22: 5 | C22: Lab | D22: X02 | E22: Wednesday | F22: 14:00 | G22: 15:50 | H22: Y105
A23: 22 | B23: 6 | C23: Lecture | D23: A01 | E23: Tuesday | F23: 10:00 | G23: 10:50 | H23: Y220
A24: 23 | B24: 6 | C24: Lecture | D24: A01 | E24: Thursday | F24: 16:00 | G24: 16:50 | H24: Y231
A25: 24 | B25: 6 | C25: Lecture | D25: A01 | E25: Friday | F25: 10:00 | G25: 10:50 | H25: WC312
A26: 25 | B26: 6 | C26: Lab | D26: X02 | E26: Tuesday | F26: 14:00 | G26: 14:50 | H26: Y131

Sheet Holidays
A1: date | B1: name | C1: classes_cancelled
A2: 2026-09-07 | B2: Labour Day | C2: TRUE
A3: 2026-09-30 | B3: National Day for Truth and Reconciliation | C3: TRUE
A4: 2026-10-12 | B4: Thanksgiving Day | C4: TRUE
A5: 2026-11-11 | B5: Remembrance Day | C5: TRUE
A6: 2026-11-12 | B6: Fall Break | C6: TRUE
A7: 2026-11-13 | B7: Fall Break | C7: TRUE

Sheet SyllabusFlags
A1: flag_id | B1: course_id | C1: item | D1: issue | E1: source | F1: resolved
A2: 1 | B2: 1 | C2: CMTC2341 Theory Assessment #1 date | D2: Weekly schedule: week 6 (Oct 5-9). Evaluation table: 'Week of September 23rd (Week 4)'. Tracker uses Sep 23. | E2: Course Syllabus CMTC2341 Fall 2026 B.pdf p3-4 | F2: FALSE
A3: 2 | B3: 1 | C3: CMTC2341 Theory Assessment #2 date | D3: Weekly schedule: week 10 (Nov 2-6). Evaluation table: 'Week of October 14th'. Tracker uses Oct 14. | E3: same | F3: FALSE
A4: 3 | B4: 1 | C4: CMTC2341 X02 lab-to-date mapping | D4: Portal gives X02 Friday dates (Sep 4, 18, Oct 2, 16, 30, Nov 13, 27, Dec 11). Syllabus lists 7 labs and says Nov 13 sessions are lost. Labs 1-7 assigned in order - INFERRED. | E4: SCHEDULE.pdf + syllabus | F4: FALSE
A5: 4 | B5: 1 | C5: CMTC2341 syllabus typo | D5: Week 2 says 'No Class on Monday, Sep. 1 - Labour Day' - Labour Day is Mon Sep 7. | E5: syllabus p3 | F5: FALSE
A6: 5 | B6: 2 | C6: CNTR2371 Theory Assessment 2 date | D6: Evaluation table: week 9. Weekly schedule prints it under the Nov 2 (week 10) row. Tracker uses Oct 27. | E6: CNTR 2371 Syllabus p3-5 | F6: FALSE
A7: 6 | B7: 2 | C7: CNTR2371 Practical In-Lab Assessments | D7: Evaluation table says 'Week 5 or 6' / 'Week 9 or 10'; weekly schedule puts X01/X02 in wk 6 (Oct 6) and wk 10 (Nov 3). | E7: same | F7: FALSE
A8: 7 | B8: 2 | C8: CNTR2371 rotational lab order (Labs 08R1/09R1/10R1) | D8: Order for Nov 17 / Nov 24 / Dec 1 not in export. | E8: syllabus | F8: FALSE
A9: 8 | B9: 2 | C9: CNTR2371 week 13/14 stray text | D9: Syllabus mentions Good Friday / Easter Monday in Nov - copy-paste from winter term; ignore. | E9: syllabus p4 | F9: FALSE
A10: 9 | B10: 3 | C10: INST2310 X02 lab dates | D10: X02 labs are Mondays; no Monday in week 1 and Sep 7 / Oct 12 are holidays. Lab sequence in tracker is INFERRED (Lab 01 on Sep 14 ...). Confirm on Brightspace. | E10: SCHEDULE.pdf + INST2310 syllabus | F10: FALSE
A11: 10 | B11: 3 | C11: INST2310 practical assessment dates | D11: Syllabus: ~week 7 and ~week 15 'see Brightspace lab exam schedule for your section'. | E11: INST2310 syllabus | F11: FALSE
A12: 11 | B12: 3 | C12: INST2310 midterm/final exact days | D12: Only 'week of' given (Sep 28, Nov 2, Dec 14). | E12: INST2310 syllabus | F12: FALSE
A13: 12 | B13: 4 | C13: INST2340 exam dates | D13: Weekly schedule: Exam 1 wk 5, Exam 2 wk 11, Exam 3 wk 15. Evaluation table: TBD. Nov 11-13 no classes affects wk 11. | E13: INST2340 syllabus | F13: FALSE
... A23: 22 | B23: 6 | C23: INST2380 ILMs | D23: Theory relies on Alberta Apprenticeship Individual Learning Modules that are not in the export. | E23: Course Pack 1.pdf p1 | F23: FALSE

Sheet Goals
A1: goal_id | B1: scope | C1: course_id | D1: description | E1: metric | F1: target_value | G1: current_value | H1: start_date | I1: end_date | J1: status
A2: 1 | B2: Weekly | D2: Self-directed study 20 h/week (NAIT guideline ~9 h/course incl. class; 6 courses) | E2: study_hours_per_week | F2: 20 | H2: 2026-09-01 | I2: 2026-12-16 | J2: Active
A3: 2 | B3: Semester | D3: Every pre-lab done the day before the lab | E3: prelabs_on_time_pct | F3: 100 | H3: 2026-09-01 | I3: 2026-12-16 | J3: Active
A4: 3 | B4: Semester | D4: Study streak of 30 days | E4: streak_days | F4: 30 | H4: 2026-09-01 | I4: 2026-12-16 | J4: Active
A5: 4 | B5: Course | C5: 2 | D5: CNTR2371 >= 80% | E5: grade_at_least | F5: 80 | H5: 2026-09-01 | I5: 2026-12-16 | J5: Active
A6: 5 | B6: Course | C6: 4 | D6: INST2340 >= 80% | E6: grade_at_least | F6: 80 | H6: 2026-09-01 | I6: 2026-12-16 | J6: Active

Sheet PracticeQuestions
A1: question_id | B1: course_id | C1: topic_id | D1: question_type | E1: question_text | F1: options | G1: answer_text | H1: explanation | I1: difficulty | J1: tags | K1: box | L1: times_attempted | M1: times_correct | N1: last_attempted | O1: next_due | P1: image_path
A2: 1 | B2: 1 | C2: 2 | D2: Short Answer | E2: In a data link, what is the DTE and what is the DCE? Give one example of each. | G2: DTE (Data Terminal Equipment) originates/receives the transmission, e.g. a computer, PLC or PAC. DCE (Data Communications Equipment) converts the signal for the transmission channel, e.g. a modem. | H2: The DTE/DCE interface (e.g. RS-232/RS-485) is the electrical connection between them; the channel (wire, fibre, radio) joins the two DCEs. | I2: 1 | J2: section1,definitions | K2: 1 | L2: 0 | M2: 0
A3: 2 | B3: 1 | C3: 4 | D3: MCQ | E3: Both devices can send and receive, but only one at a time, over a single channel. This is: | F3: Simplex|Half-duplex|Full-duplex|Multiplex | G3: Half-duplex | H3: Simplex = one direction only; full-duplex = both directions simultaneously (two channels). | I3: 1 | J3: section1 | K3: 1 | L3: 0 | M3: 0
A4: 3 | B4: 1 | C4: 3 | D4: Short Answer | E4: What is the difference between bits per second (BPS) and baud (Bd)? | G4: BPS = number of bits transmitted per second. Baud = number of discrete signal events (symbol changes) per second. They are equal only when each signal event carries one bit; with multilevel modulation BPS > baud. | H4: Common exam trap - the terms are often used interchangeably but are not the same. | I4: 2 | J4: section1,glossary | K4: 1 | L4: 0 | M4: 0
A5: 4 | B5: 2 | C5: 58 | D5: Short Answer | E5: Name the four standard components of a feedback control loop. | G5: Process, measurement (sensor/transmitter), controller, final control element (e.g. control valve). | H5: See CNTR2371 Section 1.2.1. | I5: 1 | J5: section1 | K5: 1 | L5: 0 | M5: 0
A6: 5 | B6: 2 | C6: 81 | D6: Short Answer | E6: What is reset (integral) windup and what is used to prevent it? | G6: When the controller output saturates while error persists, the integral term keeps accumulating (winding up), causing overshoot when the loop recovers. Anti-reset-windup limits on the integral term prevent it. | H6: Section 4.2 - PI controller with anti-reset windup limits. | I6: 2 | J6: section4,issues | K6: 1 | L6: 0 | M6: 0
A7: 6 | B7: 3 | C7: 121 | D7: Short Answer | E7: Define the K-factor of a turbine flow meter and state its typical units. | G7: K-factor = number of pulses generated per unit volume passing the meter (e.g. pulses/litre or pulses/gal). Flow total = pulses / K; flow rate = frequency / K. | H7: Used in Lab 04C with the MC-III totalizer. | I7: 1 | J7: section2,turbine,lab04 | K7: 1 | L7: 0 | M7: 0
A8: 7 | B8: 4 | C8: 173 | D8: MCQ | E8: A field device is a normally-closed stop pushbutton that is NOT pressed (contact closed, input ON). An XIC instruction referencing that input evaluates as: | F8: TRUE|FALSE|Depends on the rung|Undefined | G8: TRUE | H8: XIC (Examine If Closed) is true when the bit is 1 (input energized). XIO would be false. This is the classic Lab 3 pre-lab question. | I8: 2 | J8: section3,LD,lab3 | K8: 1 | L8: 0 | M8: 0
A9: 8 | B9: 4 | C9: 170 | D9: Short Answer | E9: What is the difference between a base tag and an alias tag in Studio 5000? | G9: A base tag defines memory for data; an alias tag is another name that references a base tag (or a specific I/O point) so logic can use a descriptive name. | H9: Section 2.3. | I9: 1 | J9: section2,tags | K9: 1 | L9: 0 | M9: 0
A10: 9 | B10: 6 | C10: 241 | D10: MCQ | E10: The Brightspace pre-lab quiz for an INST2380 lab must be passed (>=50%) at least how long before the lab? | F10: 5 minutes|15 minutes|1 hour|24 hours | G10: 15 minutes | H10: F2025 lab syllabus: complete >=15 min before lab, first attempt counts, max 2 h per attempt. | I10: 1 | J10: lab-rules | K10: 1 | L10: 0 | M10: 0

Sheet StudyLog
